Workbook

Sheet 2026.9.3
G1: SCR-LP | H1: 금일조립수량 | I1: ICER | J1: 금일조립수량
G2: SCR N400A
G3: SCR N450
G4: SCR 400A | I4: ICER 600A
G5: SCR 450A | I5: ICER 700A
G6: SCR 500A | I6: ICER 800A
G7: SCR N500A | I7: ICER 1000A
A8: DAMPER 조립 자재 재고현황 | G8: SCR 550A
G9: SCR N550A
G10: SCR 600A
G11: SCR N600A
G12: SCR 650A
G13: SCR 700A
G14: SCR750A
G15: SCR 800A
A17: 자재명 | B17: 재질 | C17: 수량/1대 | D17: 적용제품 | E17: 자재규격 | F17: 전일재고 | G17: 투입수량 | H17: 분실/파손 | I17: 입고수량 | J17: 현재재고 | K17: 조립가능대수 | L17: 알람
A18: Key | B18: S45c | C18: 2 | D18: SCR 400A-750A공용 | E18: 10×8×35L | F18: 310 | G18: =SUM(H4:H14)*C18 -> 0 | J18: =F18+I18-G18-H18 -> 310 | K18: =J18/C18 -> 155
A19: Key | B19: S45c | C19: 2 | D19: SCR 800A | E19: 12×8×55L | F19: 240 | G19: =H15*C19 -> 0 | J19: =F19+I19-G19-H19 -> 240 | K19: =J19/C19 -> 120
A20: Key | B20: SUS304 | C20: 2 | D20: ICER 600A | E20: 10×8×45L | F20: 76 | G20: =J4*C20 -> 0 | J20: =F20+I20-G20-H20 -> 76 | K20: =J20/C20 -> 38
A21: Key | B21: SUS304 | C21: 2 | D21: ICER 700A | E21: 12×8×58L | F21: 2 | G21: =J5*C21 -> 0 | J21: =F21+I21-G21-H21 -> 2 | K21: =J21/C21 -> 1
A22: Key | B22: SUS304 | C22: 2 | D22: ICER 800A | E22: 14×9×60L | F22: 73 | G22: =J6*C22 -> 0 | J22: =F22+I22-G22-H22 -> 73 | K22: =J22/C22 -> 36.5
A23: Key | B23: SUS304 | C23: 2 | D23: ICER 1000A | E23: 14×9×50L | F23: 78 | G23: =J7*C23 -> 0 | J23: =F23+I23-G23-H23 -> 78 | K23: =J23/C23 -> 39
A24: Dust Seal | B24: GRAPHITE | C24: 4 | D24: SCR 400A-600A | E24: 45×35×5L | F24: 304 | G24: =SUM(H2:H11)*C24 -> 0 | J24: =F24+I24-G24-H24 -> 304 | K24: =J24/C24 -> 76
A25: Dust Seal | B25: GRAPHITE | C25: 4 | D25: SCR 650A-750A | E25: 50×40×5L | F25: 150 | G25: =SUM(H12:H14)*C25 -> 0 | J25: =F25+I25-G25-H25 -> 150 | K25: =J25/C25 -> 37.5
A26: Dust Seal | B26: GRAPHITE | C26: 4 | D26: SCR 800A | E26: 60×45×7.5L | F26: 262 | G26: =H15*C26 -> 0 | J26: =F26+I26-G26-H26 -> 262 | K26: =J26/C26 -> 65.5
A27: Dust Seal | B27: GRAPHITE | C27: 4 | D27: ICER 600A | E27: 50×40×5L | F27: 206 | G27: =J4*C27 -> 0 | J27: =F27+I27-G27-H27 -> 206 | K27: =J27/C27 -> 51.5
A28: Dust Seal | B28: GRAPHITE | C28: 4 | D28: ICER 700A | E28: 55×45×5L | F28: 0 | G28: =J5*C28 -> 0 | J28: =F28+I28-G28-H28 -> 0 | K28: =J28/C28 -> 0
A29: Dust Seal | B29: GRAPHITE | C29: 4 | D29: ICER 800A/1000A공용 | E29: 60×50×5L | F29: 328 | G29: =SUM(J6:J7)*C29 -> 0 | J29: =F29+I29-G29-H29 -> 328 | K29: =J29/C29 -> 82
A30: Packing Ring | B30: GRAPHITE | C30: 8 | D30: SCR 400A-600A | E30: 45×35×5L | F30: 612 | G30: =SUM(H2:H11)*C30 -> 0 | J30: =F30+I30-G30-H30 -> 612 | K30: =J30/C30 -> 76.5
A31: Packing Ring | B31: GRAPHITE | C31: 8 | D31: SCR 650A-750A | E31: 50×40×5L | F31: 246 | G31: =SUM(H12:H14)*C31 -> 0 | J31: =F31+I31-G31-H31 -> 246 | K31: =J31/C31 -> 30.75
A32: Packing Ring | B32: GRAPHITE | C32: 8 | D32: SCR 800A | E32: 60×45×7.5 | F32: 530 | G32: =H15*C32 -> 0 | J32: =F32+I32-G32-H32 -> 530 | K32: =J32/C32 -> 66.25
A33: Packing Ring | B33: GRAPHITE | C33: 5 | D33: ICER 600A | E33: 55×40×7.5 | F33: 180 | G33: =J4*C33 -> 0 | J33: =F33+I33-G33-H33 -> 180 | K33: =J33/C33 -> 36
A34: Packing Ring | B34: GRAPHITE | C34: 5 | D34: ICER 700A | E34: 60×45×7.5 | F34: 5 | G34: =J5*C34 -> 0 | J34: =F34+I34-G34-H34 -> 5 | K34: =J34/C34 -> 1
A35: Packing Ring | B35: GRAPHITE | C35: 5 | D35: ICER 800A/1000A공용 | E35: 65×50×7.5 | F35: 380 | G35: =J7*C35 -> 0 | J35: =F35+I35-G35-H35 -> 380 | K35: =J35/C35 -> 76
A36: Space Ring | B36: EY306 | C36: 2 | D36: SCR 400A-600A | E36: 45×35×20L | F36: 79 | G36: =SUM(H2:H11)*C36 -> 0 | J36: =F36+I36-G36-H36 -> 79 | K36: =J36/C36 -> 39.5
A37: Space Ring | B37: EY306 | C37: 2 | D37: SCR 650A-750A | E37: 50×40×50L | F37: 116 | G37: =SUM(H12:H14)*C37 -> 0 | J37: =F37+I37-G37-H37 -> 116 | K37: =J37/C37 -> 58
A38: Space Ring | B38: EY306 | C38: 2 | D38: SCR 800A | E38: 60×45×50L | F38: 70 | G38: =H15*C38 -> 0 | J38: =F38+I38-G38-H38 -> 70 | K38: =J38/C38 -> 35
A39: Space Ring | B39: EY306 | C39: 2 | D39: ICER 600A | E39: 49.95×40.4×77L | F39: 68 | G39: =J4*C39 -> 0 | J39: =F39+I39-G39-H39 -> 68 | K39: =J39/C39 -> 34
A40: Space Ring | B40: EY306 | C40: 2 | D40: ICER 700A | E40: 54.95×45.4×70L | F40: 0 | G40: =J5*C40 -> 0 | J40: =F40+I40-G40-H40 -> 0 | K40: =J40/C40 -> 0
A41: Space Ring | B41: EY306 | C41: 2 | D41: ICER 800A | E41: 59.95×50.4×77L | F41: 88 | G41: =J6*C41 -> 0 | J41: =F41+I41-G41-H41 -> 88 | K41: =J41/C41 -> 44
...

Sheet 2026.9.4
G1: SCR-LP | H1: 금일조립수량 | I1: ICER | J1: 금일조립수량
G2: SCR N400A
G3: SCR N450
G4: SCR 400A | I4: ICER 600A
G5: SCR 450A | I5: ICER 700A
G6: SCR 500A | I6: ICER 800A
G7: SCR N500A | I7: ICER 1000A | J7: 2
A8: DAMPER 조립 자재 재고현황 | G8: SCR 550A
G9: SCR N550A
G10: SCR 600A
G11: SCR N600A
G12: SCR 650A
G13: SCR 700A
G14: SCR750A
G15: SCR 800A
A17: 자재명 | B17: 재질 | C17: 수량 | D17: 적용제품 | E17: 자재규격 | F17: 전일재고 | G17: 투입수량 | H17: 분실/파손 | I17: 입고수량 | J17: 현재재고 | K17: 생조립가능대수 | L17: 알람
A18: Key | B18: S45c | C18: 2 | D18: SCR 400A-750A공용 | E18: 10×8×35L | F18: ='2026.9.3'!J18 -> 310 | G18: =SUM(H4:H14)*C18 -> 0 | J18: =F18+I18-G18-H18 -> 310 | K18: =J18/C18 -> 155
A19: Key | B19: S45c | C19: 2 | D19: SCR 800A | E19: 12×8×55L | F19: 240 | G19: =H15*C19 -> 0 | J19: =F19+I19-G19-H19 -> 240 | K19: =J19/C19 -> 120
A20: Key | B20: SUS304 | C20: 2 | D20: ICER 600A | E20: 10×8×45L | F20: 76 | G20: =J4*C20 -> 0 | J20: =F20+I20-G20-H20 -> 76 | K20: =J20/C20 -> 38
A21: Key | B21: SUS304 | C21: 2 | D21: ICER 700A | E21: 12×8×58L | F21: 2 | G21: =J5*C21 -> 0 | J21: =F21+I21-G21-H21 -> 2 | K21: =J21/C21 -> 1
A22: Key | B22: SUS304 | C22: 2 | D22: ICER 800A | E22: 14×9×60L | F22: 73 | G22: =J6*C22 -> 0 | J22: =F22+I22-G22-H22 -> 73 | K22: =J22/C22 -> 36.5
A23: Key | B23: SUS304 | C23: 2 | D23: ICER 1000A | E23: 14×9×50L | F23: 78 | G23: =J7*C23 -> 4 | J23: =F23+I23-G23-H23 -> 74 | K23: =J23/C23 -> 37
A24: Dust Seal | B24: GRAPHITE | C24: 4 | D24: SCR 400A-600A | E24: 45×35×5L | F24: 304 | G24: =SUM(H2:H11)*C24 -> 0 | J24: =F24+I24-G24-H24 -> 304 | K24: =J24/C24 -> 76
A25: Dust Seal | B25: GRAPHITE | C25: 4 | D25: SCR 650A-750A | E25: 50×40×5L | F25: 150 | G25: =SUM(H12:H14)*C25 -> 0 | J25: =F25+I25-G25-H25 -> 150 | K25: =J25/C25 -> 37.5
A26: Dust Seal | B26: GRAPHITE | C26: 4 | D26: SCR 800A | E26: 60×45×7.5L | F26: 262 | G26: =H15*C26 -> 0 | J26: =F26+I26-G26-H26 -> 262 | K26: =J26/C26 -> 65.5
A27: Dust Seal | B27: GRAPHITE | C27: 4 | D27: ICER 600A | E27: 50×40×5L | F27: 206 | G27: =J4*C27 -> 0 | J27: =F27+I27-G27-H27 -> 206 | K27: =J27/C27 -> 51.5
A28: Dust Seal | B28: GRAPHITE | C28: 4 | D28: ICER 700A | E28: 55×45×5L | F28: 0 | G28: =J5*C28 -> 0 | J28: =F28+I28-G28-H28 -> 0 | K28: =J28/C28 -> 0
A29: Dust Seal | B29: GRAPHITE | C29: 4 | D29: ICER 800A/1000A공용 | E29: 60×50×5L | F29: 328 | G29: =SUM(J6:J7)*C29 -> 8 | J29: =F29+I29-G29-H29 -> 320 | K29: =J29/C29 -> 80
A30: Packing Ring | B30: GRAPHITE | C30: 8 | D30: SCR 400A-600A | E30: 45×35×5L | F30: 612 | G30: =SUM(H2:H11)*C30 -> 0 | J30: =F30+I30-G30-H30 -> 612 | K30: =J30/C30 -> 76.5
A31: Packing Ring | B31: GRAPHITE | C31: 8 | D31: SCR 650A-750A | E31: 50×40×5L | F31: 246 | G31: =SUM(H12:H14)*C31 -> 0 | J31: =F31+I31-G31-H31 -> 246 | K31: =J31/C31 -> 30.75
A32: Packing Ring | B32: GRAPHITE | C32: 8 | D32: SCR 800A | E32: 60×45×7.5 | F32: 530 | G32: =H15*C32 -> 0 | J32: =F32+I32-G32-H32 -> 530 | K32: =J32/C32 -> 66.25
A33: Packing Ring | B33: GRAPHITE | C33: 5 | D33: ICER 600A | E33: 55×40×7.5 | F33: 180 | G33: =J4*C33 -> 0 | J33: =F33+I33-G33-H33 -> 180 | K33: =J33/C33 -> 36
A34: Packing Ring | B34: GRAPHITE | C34: 5 | D34: ICER 700A | E34: 60×45×7.5 | F34: 5 | G34: =J5*C34 -> 0 | J34: =F34+I34-G34-H34 -> 5 | K34: =J34/C34 -> 1
A35: Packing Ring | B35: GRAPHITE | C35: 5 | D35: ICER 800A/1000A공용 | E35: 65×50×7.5 | F35: 380 | G35: =J7*C35 -> 10 | J35: =F35+I35-G35-H35 -> 370 | K35: =J35/C35 -> 74
A36: Space Ring | B36: EY306 | C36: 2 | D36: SCR 400A-600A | E36: 45×35×20L | F36: 79 | G36: =SUM(H2:H11)*C36 -> 0 | J36: =F36+I36-G36-H36 -> 79 | K36: =J36/C36 -> 39.5
A37: Space Ring | B37: EY306 | C37: 2 | D37: SCR 650A-750A | E37: 50×40×50L | F37: 116 | G37: =SUM(H12:H14)*C37 -> 0 | J37: =F37+I37-G37-H37 -> 116 | K37: =J37/C37 -> 58
A38: Space Ring | B38: EY306 | C38: 2 | D38: SCR 800A | E38: 60×45×50L | F38: 70 | G38: =H15*C38 -> 0 | J38: =F38+I38-G38-H38 -> 70 | K38: =J38/C38 -> 35
A39: Space Ring | B39: EY306 | C39: 2 | D39: ICER 600A | E39: 49.95×40.4×77L | F39: 68 | G39: =J4*C39 -> 0 | J39: =F39+I39-G39-H39 -> 68 | K39: =J39/C39 -> 34
A40: Space Ring | B40: EY306 | C40: 2 | D40: ICER 700A | E40: 54.95×45.4×70L | F40: 0 | G40: =J5*C40 -> 0 | J40: =F40+I40-G40-H40 -> 0 | K40: =J40/C40 -> 0
A41: Space Ring | B41: EY306 | C41: 2 | D41: ICER 800A | E41: 59.95×50.4×77L | F41: 88 | G41: =J6*C41 -> 0 | J41: =F41+I41-G41-H41 -> 88 | K41: =J41/C41 -> 44
...

Sheet 2026.9.7
H1: DAMPER 모델별 조립수량
H2: SCR-LP | I2: 금일조립수량 | J2: ICER | K2: 금일조립수량
H3: SCR N400A
H4: SCR N450
H5: SCR 400A | J5: ICER 600A
H6: SCR 450A | J6: ICER 700A
H7: SCR 500A | J7: ICER 800A
H8: SCR N500A | J8: ICER 1000A
B9: DAMPER 조립 자재 재고현황 | H9: SCR 550A
H10: SCR N550A
H11: SCR 600A
H12: SCR N600A
H13: SCR 650A
H14: SCR 700A
H15: SCR750A
H16: SCR 800A
H17: SCR 5K 400A(세)
H18: SCR 5K 600A(세)
H19: SCR 2200A
H20: SCR 2400A
A22: 제품명 | B22: 자재명 | C22: 재질 | D22: 수량/1대 | E22: 적용모델 | F22: 자재규격 | G22: 전일재고 | H22: 투입수량 | I22: 분실/파손 | J22: 입고수량 | K22: 현재재고 | L22: 조립가능대수 | M22: 알람
A23: DAMPER | B23: Key | C23: S45C | D23: 2 | E23: SCR 400A-750A | F23: 10×8×35L | G23: ='2026.9.4'!J18 -> 310 | H23: =SUM(I3:I15)*D23 -> 0 | K23: =G23+J23-H23-I23 -> 310 | L23: =K23/D23 -> 155 | M23: =IF(L23<=10,119,"")
A24: DAMPER | B24: Key | C24: S45C | D24: 2 | E24: SCR 800A | F24: 12×8×55L | G24: ='2026.9.4'!J19 -> 240 | H24: =I16*D24 -> 0 | K24: =G24+J24-H24-I24 -> 240 | L24: =K24/D24 -> 120 | M24: =IF(L24<=10,119,"")
A25: DAMPER | B25: Key | C25: S45C | D25: 2 | E25: SCR 5K 400A(세) | F25: 10×8×35L | G25: 17 | H25: =I17*D25 -> 0 | K25: =G25+J25-H25-I25 -> 17 | L25: =K25/D25 -> 8.5 | M25: =IF(L25<=10,119,"") -> 119
A26: DAMPER | B26: Key | C26: S45C | D26: 2 | E26: SCR 5K 600A(세) | G26: 17 | H26: =I18*D26 -> 0 | K26: =G26+J26-H26-I26 -> 17 | L26: =K26/D26 -> 8.5 | M26: =IF(L26<=10,119,"") -> 119
A27: DAMPER | B27: Key | C27: S45C | D27: 2 | E27: SCR 2200A/2400A공용 | G27: 6 | H27: =SUM(I19:I20)*D27 -> 0 | K27: =G27+J27-H27-I27 -> 6 | L27: =K27/D27 -> 3 | M27: =IF(L27<=10,119,"") -> 119
A28: DAMPER | B28: Key | C28: SUS304 | D28: 2 | E28: ICER 600A | F28: 10×8×45L | G28: ='2026.9.4'!J20 -> 76 | H28: =K5*D28 -> 0 | K28: =G28+J28-H28-I28 -> 76 | L28: =K28/D28 -> 38 | M28: =IF(L28<=10,119,"")
A29: DAMPER | B29: Key | C29: SUS304 | D29: 2 | E29: ICER 700A | F29: 12×8×58L | G29: ='2026.9.4'!J21 -> 2 | H29: =K6*D29 -> 0 | K29: =G29+J29-H29-I29 -> 2 | L29: =K29/D29 -> 1 | M29: =IF(L29<=10,119,"") -> 119
A30: DAMPER | B30: Key | C30: SUS304 | D30: 2 | E30: ICER 800A | F30: 14×9×60L | G30: ='2026.9.4'!J22 -> 73 | H30: =K7*D30 -> 0 | K30: =G30+J30-H30-I30 -> 73 | L30: =K30/D30 -> 36.5 | M30: =IF(L30<=10,119,"")
A31: DAMPER | B31: Key | C31: SUS304 | D31: 2 | E31: ICER 1000A | F31: 14×9×50L | G31: ='2026.9.4'!J23 -> 74 | H31: =K8*D31 -> 0 | K31: =G31+J31-H31-I31 -> 74 | L31: =K31/D31 -> 37 | M31: =IF(L31<=10,119,"")
A32: DAMPER | B32: Key(Adapter) | C32: S45C | D32: 2 | E32: SCR 2200A/2400A공용 | G32: 8 | H32: =SUM(I19:I20)*D32 -> 0 | K32: =G32+J32-H32-I32 -> 8 | L32: =K32/D32 -> 4 | M32: =IF(L32<=10,119,"") -> 119
A33: DAMPER | B33: Dust Seal | C33: GRAPHITE | D33: 4 | E33: SCR 400A-600A | F33: 45×35×5L | G33: ='2026.9.4'!J24 -> 304 | H33: =SUM(I3:I12)*D33 -> 0 | K33: =G33+J33-H33-I33 -> 304 | L33: =K33/D33 -> 76 | M33: =IF(L33<=10,119,"")
A34: DAMPER | B34: Dust Seal | C34: GRAPHITE | D34: 4 | E34: SCR 650A-750A | F34: 50×40×5L | G34: ='2026.9.4'!J25 -> 150 | H34: =SUM(I13:I15)*D34 -> 0 | K34: =G34+J34-H34-I34 -> 150 | L34: =K34/D34 -> 37.5 | M34: =IF(L34<=10,119,"")
A35: DAMPER | B35: Dust Seal | C35: GRAPHITE | D35: 4 | E35: SCR 800A | F35: 60×45×7.5L | G35: ='2026.9.4'!J26 -> 262 | H35: =I16*D35 -> 0 | K35: =G35+J35-H35-I35 -> 262 | L35: =K35/D35 -> 65.5 | M35: =IF(L35<=10,119,"")
A36: DAMPER | B36: Dust Seal | C36: GRAPHITE | D36: 4 | E36: SCR 5K 400A(세) | G36: 6 | H36: =I17*D36 -> 0 | K36: =G36+J36-H36-I36 -> 6 | L36: =K36/D36 -> 1.5 | M36: =IF(L36<=10,119,"") -> 119
A37: DAMPER | B37: Dust Seal | C37: GRAPHITE | D37: 4 | E37: SCR 5K 600A(세) | G37: 6 | H37: =I18*D37 -> 0 | K37: =G37+J37-H37-I37 -> 6 | L37: =K37/D37 -> 1.5 | M37: =IF(L37<=10,119,"") -> 119
A38: DAMPER | B38: Dust Seal | C38: GRAPHITE | D38: 2 | E38: SCR 2200A | G38: 2 | H38: =I19*D38 -> 0 | K38: =G38+J38-H38-I38 -> 2 | L38: =K38/D38 -> 1 | M38: =IF(L38<=10,119,"") -> 119
A39: DAMPER | B39: Dust Seal | C39: GRAPHITE | D39: 2 | E39: SCR 2400A | G39: 4 | H39: =I20*D39 -> 0 | K39: =G39+J39-H39-I39 -> 4 | L39: =K39/D39 -> 2 | M39: =IF(L39<=10,119,"") -> 119
A40: DAMPER | B40: Dust Seal | C40: GRAPHITE | D40: 4 | E40: ICER 600A | F40: 50×40×5L | G40: ='2026.9.4'!J27 -> 206 | H40: =K5*D40 -> 0 | K40: =G40+J40-H40-I40 -> 206 | L40: =K40/D40 -> 51.5 | M40: =IF(L40<=10,119,"")
A41: DAMPER | B41: Dust Seal | C41: GRAPHITE | D41: 4 | E41: ICER 700A | F41: 55×45×5L | G41: ='2026.9.4'!J28 -> 0 | H41: =K6*D41 -> 0 | K41: =G41+J41-H41-I41 -> 0 | L41: =K41/D41 -> 0 | M41: =IF(L41<=10,119,"") -> 119
...

Sheet 2026.9.8
H1: DAMPER 모델별 조립수량
H2: SCR-LP | I2: 금일조립수량 | J2: ICER | K2: 금일조립수량 | L2: SCR-LP | M2: 누계 | N2: ICER | O2: 누계
H3: SCR N400A | L3: SCR N400A
H4: SCR N450 | L4: SCR N450
H5: SCR 400A | J5: ICER 600A | L5: SCR 400A | N5: ICER 600A
H6: SCR 450A | J6: ICER 700A | L6: SCR 450A | N6: ICER 700A
H7: SCR 500A | J7: ICER 800A | L7: SCR 500A | N7: ICER 800A
H8: SCR N500A | J8: ICER 1000A | L8: SCR N500A | N8: ICER 1000A | O8: 1
H9: SCR 5K N500A | L9: SCR 5K N500A
B10: DAMPER 조립 자재 재고현황 | H10: SCR 550A | L10: SCR 550A
H11: SCR N550A | L11: SCR N550A
H12: SCR 5K N550A | L12: SCR 5K N550A
H13: SCR 600A | L13: SCR 600A
H14: SCR N600A | L14: SCR N600A
H15: SCR 5K N600A | L15: SCR 5K N600A
H16: SCR 650A | L16: SCR 650A
H17: SCR 5K 650A | L17: SCR 5K 650A
H18: SCR 700A | L18: SCR 700A
H19: SCR 750A | L19: SCR 750A
H20: SCR 800A | L20: SCR 800A
H21: SCR 5K 400A(세) | L21: SCR 5K 400A(세)
H22: SCR 5K 600A(세) | L22: SCR 5K 600A(세)
H23: SCR 2200A | I23: 1 | L23: SCR 2200A | M23: 1
H24: SCR 2400A | L24: SCR 2400A
A26: 제품명 | B26: 자재명 | C26: 재질 | D26: 수량/1대 | E26: 적용모델 | F26: 자재규격 | G26: 전일재고 | H26: 투입수량 | I26: 분실/파손 | J26: 입고수량 | K26: 현재재고 | L26: 조립가능대수 | M26: 안전재고알람
A27: DAMPER | B27: Key | C27: S45C | D27: 2 | E27: SCR 400A-750A | F27: 10×8×35L | G27: ='2026.9.7'!K23 -> 310 | H27: =SUM(I3:I19)*D27 -> 0 | K27: =G27+J27-H27-I27 -> 310 | L27: =K27/D27 -> 155 | M27: =IF(L27<=10,119,"")
A28: DAMPER | B28: Key | C28: S45C | D28: 2 | E28: SCR 800A | F28: 12×8×55L | G28: ='2026.9.7'!K24 -> 240 | H28: =I20*D28 -> 0 | K28: =G28+J28-H28-I28 -> 240 | L28: =K28/D28 -> 120 | M28: =IF(L28<=10,119,"")
A29: DAMPER | B29: Key | C29: S45C | D29: 2 | E29: SCR 5K 400A(세) | F29: 10×8×35L | G29: ='2026.9.7'!K25 -> 17 | H29: =I21*D29 -> 0 | K29: =G29+J29-H29-I29 -> 17 | L29: =K29/D29 -> 8.5 | M29: =IF(L29<=10,119,"") -> 119
A30: DAMPER | B30: Key | C30: S45C | D30: 2 | E30: SCR 5K 600A(세) | F30: 14×9×55L | G30: ='2026.9.7'!K26 -> 17 | H30: =I22*D30 -> 0 | K30: =G30+J30-H30-I30 -> 17 | L30: =K30/D30 -> 8.5 | M30: =IF(L30<=10,119,"") -> 119
A31: DAMPER | B31: Key | C31: S45C | D31: 2 | E31: SCR 2200A/2400A공용 | F31: 25×14×80L | G31: ='2026.9.7'!K27 -> 6 | H31: =SUM(I23:I24)*D31 -> 2 | K31: =G31+J31-H31-I31 -> 4 | L31: =K31/D31 -> 2 | M31: =IF(L31<=10,119,"") -> 119
A32: DAMPER | B32: Key | C32: SUS304 | D32: 2 | E32: ICER 600A | F32: 10×8×45L | G32: ='2026.9.7'!K28 -> 76 | H32: =K5*D32 -> 0 | K32: =G32+J32-H32-I32 -> 76 | L32: =K32/D32 -> 38 | M32: =IF(L32<=10,119,"")
A33: DAMPER | B33: Key | C33: SUS304 | D33: 2 | E33: ICER 700A | F33: 12×8×58L | G33: ='2026.9.7'!K29 -> 2 | H33: =K6*D33 -> 0 | K33: =G33+J33-H33-I33 -> 2 | L33: =K33/D33 -> 1 | M33: =IF(L33<=10,119,"") -> 119
A34: DAMPER | B34: Key | C34: SUS304 | D34: 2 | E34: ICER 800A | F34: 14×9×60L | G34: ='2026.9.7'!K30 -> 73 | H34: =K7*D34 -> 0 | K34: =G34+J34-H34-I34 -> 73 | L34: =K34/D34 -> 36.5 | M34: =IF(L34<=10,119,"")
A35: DAMPER | B35: Key | C35: SUS304 | D35: 2 | E35: ICER 1000A | F35: 14×9×50L | G35: ='2026.9.7'!K31 -> 74 | H35: =K8*D35 -> 0 | K35: =G35+J35-H35-I35 -> 74 | L35: =K35/D35 -> 37 | M35: =IF(L35<=10,119,"")
A36: DAMPER | B36: Key(Adapter) | C36: S45C | D36: 2 | E36: SCR 2200A/2400A공용 | F36: 150×28×16T | G36: ='2026.9.7'!K32 -> 8 | H36: =SUM(I23:I24)*D36 -> 2 | K36: =G36+J36-H36-I36 -> 6 | L36: =K36/D36 -> 3 | M36: =IF(L36<=10,119,"") -> 119
A37: DAMPER | B37: Dust Seal | C37: GRAPHITE | D37: 4 | E37: SCR 400A-600A | F37: 45×35×5L | G37: ='2026.9.7'!K33 -> 304 | H37: =SUM(I3:I14)*D37 -> 0 | K37: =G37+J37-H37-I37 -> 304 | L37: =K37/D37 -> 76 | M37: =IF(L37<=10,119,"")
A38: DAMPER | B38: Dust Seal | C38: GRAPHITE | D38: 4 | E38: SCR 650A-750A | F38: 50×40×5L | G38: ='2026.9.7'!K34 -> 150 | H38: =SUM(I16:I19)*D38 -> 0 | K38: =G38+J38-H38-I38 -> 150 | L38: =K38/D38 -> 37.5 | M38: =IF(L38<=10,119,"")
A39: DAMPER | B39: Dust Seal | C39: GRAPHITE | D39: 4 | E39: SCR 800A | F39: 60×45×7.5L | G39: ='2026.9.7'!K35 -> 262 | H39: =I20*D39 -> 0 | K39: =G39+J39-H39-I39 -> 262 | L39: =K39/D39 -> 65.5 | M39: =IF(L39<=10,119,"")
A40: DAMPER | B40: Dust Seal | C40: GRAPHITE | D40: 4 | E40: SCR 5K 400A(세) | F40: 40×30×5T | G40: ='2026.9.7'!K36 -> 6 | H40: =I21*D40 -> 0 | K40: =G40+J40-H40-I40 -> 6 | L40: =K40/D40 -> 1.5 | M40: =IF(L40<=10,119,"") -> 119
A41: DAMPER | B41: Dust Seal | C41: GRAPHITE | D41: 4 | E41: SCR 5K 600A(세) | F41: 60×50×5T | G41: ='2026.9.7'!K37 -> 6 | H41: =I22*D41 -> 0 | K41: =G41+J41-H41-I41 -> 6 | L41: =K41/D41 -> 1.5 | M41: =IF(L41<=10,119,"") -> 119
...

Sheet 2026.9.9
G3: DAMPER 모델별 조립실적(2026.9.8 ~ )
G4: SCR-LP | H4: 금일조립수량 | I4: ICER | J4: 금일조립수량 | K4: SCR-LP | L4: 누계 | M4: ICER | N4: 누계
G5: SCR N400A | K5: SCR N400A | L5: =H6+'2026.9.8'!M3 -> 0
G6: SCR N450 | K6: SCR N450 | L6: =H7+'2026.9.8'!M4 -> 0
G7: SCR 400A | I7: ICER 600A | K7: SCR 400A | L7: =H8+'2026.9.8'!M5 -> 0 | M7: ICER 600A | N7: =J7+'2026.9.8'!O5 -> 0
G8: SCR 450A | I8: ICER 700A | K8: SCR 450A | L8: =H9+'2026.9.8'!M6 -> 0 | M8: ICER 700A | N8: =J8+'2026.9.8'!O6 -> 0
G9: SCR 500A | I9: ICER 800A | J9: 2 | K9: SCR 500A | L9: =H10+'2026.9.8'!M7 -> 0 | M9: ICER 800A | N9: =J9+'2026.9.8'!O7 -> 2
G10: SCR N500A | I10: ICER 1000A | J10: 3 | K10: SCR N500A | L10: =H11+'2026.9.8'!M8 -> 0 | M10: ICER 1000A | N10: =J10+'2026.9.8'!O8 -> 4
G11: SCR 5K N500A | K11: SCR 5K N500A | L11: =H12+'2026.9.8'!M9 -> 0
A12: DAMPER 조립 자재 재고현황 | G12: SCR 550A | K12: SCR 550A | L12: =H13+'2026.9.8'!M10 -> 0
G13: SCR N550A | K13: SCR N550A | L13: =H14+'2026.9.8'!M11 -> 0
G14: SCR 5K N550A | K14: SCR 5K N550A | L14: =H15+'2026.9.8'!M12 -> 0
G15: SCR 600A | K15: SCR 600A | L15: =H16+'2026.9.8'!M13 -> 0
G16: SCR N600A | K16: SCR N600A | L16: =H17+'2026.9.8'!M14 -> 0
G17: SCR 5K N600A | K17: SCR 5K N600A | L17: =H18+'2026.9.8'!M15 -> 0
G18: SCR 650A | K18: SCR 650A | L18: =H19+'2026.9.8'!M16 -> 0
G19: SCR 5K 650A | K19: SCR 5K 650A | L19: =H20+'2026.9.8'!M17 -> 0
G20: SCR 700A | K20: SCR 700A | L20: =H21+'2026.9.8'!M18 -> 0
G21: SCR 750A | K21: SCR 750A | L21: =H22+'2026.9.8'!M19 -> 0
G22: SCR 800A | K22: SCR 800A | L22: =H23+'2026.9.8'!M20 -> 0
G23: SCR 5K 400A(세) | K23: SCR 5K 400A(세) | L23: =H24+'2026.9.8'!M21 -> 0
G24: SCR 5K 600A(세) | K24: SCR 5K 600A(세) | L24: =H25+'2026.9.8'!M22 -> 0
... G26: SCR 2400A | K26: SCR 2400A | L26: =H27+'2026.9.8'!M24 -> 0
A28: 자재명 | B28: 재질 | C28: 수량/1대 | D28: 적용모델 | E28: 자재규격 | F28: 전일재고 | G28: 투입수량 | H28: 분실/파손 | I28: 입고수량 | J28: 현재재고 | K28: 조립가능대수 | L28: 안전재고알람
A29: Key | B29: S45C | C29: 2 | D29: SCR 400A-750A공용 | E29: 10×8×35L | F29: ='2026.9.8'!K27 -> 310 | G29: =SUM(H5:H21)*C29 -> 0 | J29: =F29+I29-G29-H29 -> 310 | K29: =J29/C29 -> 155 | L29: =IF(K29<=10,119,"")
A30: Key | B30: S45C | C30: 2 | D30: SCR 800A | E30: 12×8×55L | F30: ='2026.9.8'!K28 -> 240 | G30: =H22*C30 -> 0 | J30: =F30+I30-G30-H30 -> 240 | K30: =J30/C30 -> 120 | L30: =IF(K30<=10,119,"")
A31: Key | B31: S45C | C31: 2 | D31: SCR 5K 400A(세) | E31: 10×8×35L | F31: ='2026.9.8'!K29 -> 17 | G31: =H23*C31 -> 0 | J31: =F31+I31-G31-H31 -> 17 | K31: =J31/C31 -> 8.5 | L31: =IF(K31<=10,119,"") -> 119
A32: Key | B32: S45C | C32: 2 | D32: SCR 5K 600A(세) | E32: 14×9×55L | F32: ='2026.9.8'!K30 -> 17 | G32: =H24*C32 -> 0 | J32: =F32+I32-G32-H32 -> 17 | K32: =J32/C32 -> 8.5 | L32: =IF(K32<=10,119,"") -> 119
A33: Key | B33: S45C | C33: 2 | D33: SCR 2200A/2400A공용 | E33: 25×14×80L | F33: ='2026.9.8'!K31 -> 4 | G33: =SUM(H25:H26)*C33 -> 0 | J33: =F33+I33-G33-H33 -> 4 | K33: =J33/C33 -> 2 | L33: =IF(K33<=10,119,"") -> 119
A34: Key | B34: SUS304 | C34: 2 | D34: ICER 600A | E34: 10×8×45L | F34: ='2026.9.8'!K32 -> 76 | G34: =J7*C34 -> 0 | J34: =F34+I34-G34-H34 -> 76 | K34: =J34/C34 -> 38 | L34: =IF(K34<=10,119,"")
A35: Key | B35: SUS304 | C35: 2 | D35: ICER 700A | E35: 12×8×58L | F35: ='2026.9.8'!K33 -> 2 | G35: =J8*C35 -> 0 | J35: =F35+I35-G35-H35 -> 2 | K35: =J35/C35 -> 1 | L35: =IF(K35<=10,119,"") -> 119
A36: Key | B36: SUS304 | C36: 2 | D36: ICER 800A | E36: 14×9×60L | F36: ='2026.9.8'!K34 -> 73 | G36: =J9*C36 -> 4 | J36: =F36+I36-G36-H36 -> 69 | K36: =J36/C36 -> 34.5 | L36: =IF(K36<=10,119,"")
A37: Key | B37: SUS304 | C37: 2 | D37: ICER 1000A | E37: 14×9×50L | F37: ='2026.9.8'!K35 -> 74 | G37: =J10*C37 -> 6 | J37: =F37+I37-G37-H37 -> 68 | K37: =J37/C37 -> 34 | L37: =IF(K37<=10,119,"")
A38: Key(Adapter) | B38: S45C | C38: 2 | D38: SCR 2200A/2400A공용 | E38: 150×28×16T | F38: ='2026.9.8'!K36 -> 6 | G38: =SUM(H25:H26)*C38 -> 0 | J38: =F38+I38-G38-H38 -> 6 | K38: =J38/C38 -> 3 | L38: =IF(K38<=10,119,"") -> 119
A39: Dust Seal | B39: GRAPHITE | C39: 4 | D39: SCR 400A-600A공용 | E39: 45×35×5L | F39: ='2026.9.8'!K37 -> 304 | G39: =SUM(H5:H16)*C39 -> 0 | J39: =F39+I39-G39-H39 -> 304 | K39: =J39/C39 -> 76 | L39: =IF(K39<=10,119,"")
A40: Dust Seal | B40: GRAPHITE | C40: 4 | D40: SCR 650A-750A공용 | E40: 50×40×5L | F40: ='2026.9.8'!K38 -> 150 | G40: =SUM(H18:H21)*C40 -> 0 | J40: =F40+I40-G40-H40 -> 150 | K40: =J40/C40 -> 37.5 | L40: =IF(K40<=10,119,"")
A41: Dust Seal | B41: GRAPHITE | C41: 4 | D41: SCR 800A | E41: 60×45×7.5L | F41: ='2026.9.8'!K39 -> 262 | G41: =H22*C41 -> 0 | J41: =F41+I41-G41-H41 -> 262 | K41: =J41/C41 -> 65.5 | L41: =IF(K41<=10,119,"")
A42: Dust Seal | B42: GRAPHITE | C42: 4 | D42: SCR 5K 400A(세) | E42: 40×30×5T | F42: ='2026.9.8'!K40 -> 6 | G42: =H23*C42 -> 0 | J42: =F42+I42-G42-H42 -> 6 | K42: =J42/C42 -> 1.5 | L42: =IF(K42<=10,119,"") -> 119
A43: Dust Seal | B43: GRAPHITE | C43: 4 | D43: SCR 5K 600A(세) | E43: 60×50×5T | F43: ='2026.9.8'!K41 -> 6 | G43: =H24*C43 -> 0 | J43: =F43+I43-G43-H43 -> 6 | K43: =J43/C43 -> 1.5 | L43: =IF(K43<=10,119,"") -> 119
A44: Dust Seal | B44: GRAPHITE | C44: 2 | D44: SCR 2200A | E44: 110×90×10T | F44: ='2026.9.8'!K42 -> 0 | G44: =H25*C44 -> 0 | J44: =F44+I44-G44-H44 -> 0 | K44: =J44/C44 -> 0 | L44: =IF(K44<=10,119,"") -> 119
...

Sheet 2026.9.10
G3: DAMPER 모델별 조립실적(2026.9.8~)
G4: SCR-LP | H4: 금일조립수량 | I4: ICER | J4: 금일조립수량 | K4: SCR-LP | L4: 누계 | M4: ICER | N4: 누계
G5: SCR N400A | K5: SCR N400A | L5: ='2026.9.9'!L5+H5 -> 0
G6: SCR N450 | K6: SCR N450 | L6: ='2026.9.9'!L6+H6 -> 0
G7: SCR 400A | I7: ICER 600A | K7: SCR 400A | L7: ='2026.9.9'!L7+H7 -> 0 | M7: ICER 600A | N7: ='2026.9.9'!N7+J7 -> 0
G8: SCR 450A | I8: ICER 700A | K8: SCR 450A | L8: ='2026.9.9'!L8+H8 -> 0 | M8: ICER 700A | N8: ='2026.9.9'!N8+J8 -> 0
G9: SCR 500A | I9: ICER 800A | J9: 6 | K9: SCR 500A | L9: ='2026.9.9'!L9+H9 -> 0 | M9: ICER 800A | N9: ='2026.9.9'!N9+J9 -> 8
G10: SCR N500A | I10: ICER 1000A | K10: SCR N500A | L10: ='2026.9.9'!L10+H10 -> 0 | M10: ICER 1000A | N10: ='2026.9.9'!N10+J10 -> 4
G11: SCR 5K N500A | K11: SCR 5K N500A | L11: ='2026.9.9'!L11+H11 -> 0
A12: DAMPER 조립 자재 재고현황 | G12: SCR 550A | K12: SCR 550A | L12: ='2026.9.9'!L12+H12 -> 0
G13: SCR N550A | K13: SCR N550A | L13: ='2026.9.9'!L13+H13 -> 0
G14: SCR 5K N550A | K14: SCR 5K N550A | L14: ='2026.9.9'!L14+H14 -> 0
G15: SCR 600A | K15: SCR 600A | L15: ='2026.9.9'!L15+H15 -> 0
G16: SCR N600A | K16: SCR N600A | L16: ='2026.9.9'!L16+H16 -> 0
G17: SCR 5K N600A | K17: SCR 5K N600A | L17: ='2026.9.9'!L17+H17 -> 0
G18: SCR 650A | K18: SCR 650A | L18: ='2026.9.9'!L18+H18 -> 0
G19: SCR 5K 650A | K19: SCR 5K 650A | L19: ='2026.9.9'!L19+H19 -> 0
G20: SCR 700A | K20: SCR 700A | L20: ='2026.9.9'!L20+H20 -> 0
G21: SCR 750A | K21: SCR 750A | L21: ='2026.9.9'!L21+H21 -> 0
G22: SCR 800A | K22: SCR 800A | L22: ='2026.9.9'!L22+H22 -> 0
G23: SCR 5K 400A(세) | K23: SCR 5K 400A(세) | L23: ='2026.9.9'!L23+H23 -> 0
G24: SCR 5K 600A(세) | K24: SCR 5K 600A(세) | L24: ='2026.9.9'!L24+H24 -> 0
... G26: SCR 2400A | K26: SCR 2400A | L26: ='2026.9.9'!L26+H26 -> 0
L27: =SUM(L5:L26) -> 1 | N27: =SUM(N5:N26) -> 12
A29: 자재명 | B29: 재질 | C29: 수량/1대 | D29: 적용모델 | E29: 자재규격 | F29: 전일재고 | G29: 투입수량 | H29: 분실/파손 | I29: 입고수량 | J29: 현재재고 | K29: 조립가능대수 | L29: 안전재고알람
A30: Key | B30: S45C | C30: 2 | D30: SCR 400A-750A공용 | E30: 10×8×35L | F30: ='2026.9.9'!J29 -> 310 | G30: =SUM(H5:H21)*C30 -> 0 | J30: =F30+I30-G30-H30 -> 310 | K30: =J30/C30 -> 155 | L30: =IF(K30<=10,119,"")
A31: Key | B31: S45C | C31: 2 | D31: SCR 800A | E31: 12×8×55L | F31: ='2026.9.9'!J30 -> 240 | G31: =H22*C31 -> 0 | J31: =F31+I31-G31-H31 -> 240 | K31: =J31/C31 -> 120 | L31: =IF(K31<=10,119,"")
A32: Key | B32: S45C | C32: 2 | D32: SCR 5K 400A(세) | E32: 10×8×35L | F32: ='2026.9.9'!J31 -> 17 | G32: =H23*C32 -> 0 | J32: =F32+I32-G32-H32 -> 17 | K32: =J32/C32 -> 8.5 | L32: =IF(K32<=10,119,"") -> 119
A33: Key | B33: S45C | C33: 2 | D33: SCR 5K 600A(세) | E33: 14×9×55L | F33: ='2026.9.9'!J32 -> 17 | G33: =H24*C33 -> 0 | J33: =F33+I33-G33-H33 -> 17 | K33: =J33/C33 -> 8.5 | L33: =IF(K33<=10,119,"") -> 119
A34: Key | B34: S45C | C34: 2 | D34: SCR 2200A/2400A공용 | E34: 25×14×80L | F34: ='2026.9.9'!J33 -> 4 | G34: =SUM(H25:H26)*C34 -> 0 | J34: =F34+I34-G34-H34 -> 4 | K34: =J34/C34 -> 2 | L34: =IF(K34<=10,119,"") -> 119
A35: Key | B35: SUS304 | C35: 2 | D35: ICER 600A | E35: 10×8×45L | F35: ='2026.9.9'!J34 -> 76 | G35: =J7*C35 -> 0 | J35: =F35+I35-G35-H35 -> 76 | K35: =J35/C35 -> 38 | L35: =IF(K35<=10,119,"")
A36: Key | B36: SUS304 | C36: 2 | D36: ICER 700A | E36: 12×8×58L | F36: ='2026.9.9'!J35 -> 2 | G36: =J8*C36 -> 0 | J36: =F36+I36-G36-H36 -> 2 | K36: =J36/C36 -> 1 | L36: =IF(K36<=10,119,"") -> 119
A37: Key | B37: SUS304 | C37: 2 | D37: ICER 800A | E37: 14×9×60L | F37: ='2026.9.9'!J36 -> 69 | G37: =J9*C37 -> 12 | J37: =F37+I37-G37-H37 -> 57 | K37: =J37/C37 -> 28.5 | L37: =IF(K37<=10,119,"")
A38: Key | B38: SUS304 | C38: 2 | D38: ICER 1000A | E38: 14×9×50L | F38: ='2026.9.9'!J37 -> 68 | G38: =J10*C38 -> 0 | J38: =F38+I38-G38-H38 -> 68 | K38: =J38/C38 -> 34 | L38: =IF(K38<=10,119,"")
A39: Key(Adapter) | B39: S45C | C39: 2 | D39: SCR 2200A/2400A공용 | E39: 150×28×16T | F39: ='2026.9.9'!J38 -> 6 | G39: =SUM(H25:H26)*C39 -> 0 | J39: =F39+I39-G39-H39 -> 6 | K39: =J39/C39 -> 3 | L39: =IF(K39<=10,119,"") -> 119
A40: Dust Seal | B40: GRAPHITE | C40: 4 | D40: SCR 400A-600A공용 | E40: 45×35×5L | F40: ='2026.9.9'!J39 -> 304 | G40: =SUM(H5:H16)*C40 -> 0 | J40: =F40+I40-G40-H40 -> 304 | K40: =J40/C40 -> 76 | L40: =IF(K40<=10,119,"")
A41: Dust Seal | B41: GRAPHITE | C41: 4 | D41: SCR 650A-750A공용 | E41: 50×40×5L | F41: ='2026.9.9'!J40 -> 150 | G41: =SUM(H18:H21)*C41 -> 0 | J41: =F41+I41-G41-H41 -> 150 | K41: =J41/C41 -> 37.5 | L41: =IF(K41<=10,119,"")
A42: Dust Seal | B42: GRAPHITE | C42: 4 | D42: SCR 800A | E42: 60×45×7.5L | F42: ='2026.9.9'!J41 -> 262 | G42: =H22*C42 -> 0 | J42: =F42+I42-G42-H42 -> 262 | K42: =J42/C42 -> 65.5 | L42: =IF(K42<=10,119,"")
A43: Dust Seal | B43: GRAPHITE | C43: 4 | D43: SCR 5K 400A(세) | E43: 40×30×5T | F43: ='2026.9.9'!J42 -> 6 | G43: =H23*C43 -> 0 | J43: =F43+I43-G43-H43 -> 6 | K43: =J43/C43 -> 1.5 | L43: =IF(K43<=10,119,"") -> 119
A44: Dust Seal | B44: GRAPHITE | C44: 4 | D44: SCR 5K 600A(세) | E44: 60×50×5T | F44: ='2026.9.9'!J43 -> 6 | G44: =H24*C44 -> 0 | J44: =F44+I44-G44-H44 -> 6 | K44: =J44/C44 -> 1.5 | L44: =IF(K44<=10,119,"") -> 119
...

Sheet 2026.9.11
G2: DAMPER 모델별 조립실적(2026.9.8~) | O2: DAMPER 모델별 조립계획(2026.10)
G3: SCR-LP | H3: 금일조립수량 | I3: ICER | J3: 금일조립수량 | K3: SCR-LP | L3: 누계 | M3: ICER | N3: 누계 | O3: SCR-LP | P3: 10월계획 | Q3: ICER | R3: 10월계획
G4: SCR N400A | K4: SCR N400A | L4: =H4+'2026.9.10'!L5 -> 0 | O4: SCR N400A
G5: SCR N450 | K5: SCR N450 | L5: =H5+'2026.9.10'!L6 -> 0 | O5: SCR N450 | P5: 6
G6: SCR 400A | I6: ICER 600A | K6: SCR 400A | L6: =H6+'2026.9.10'!L7 -> 0 | M6: ICER 600A | N6: ='2026.9.10'!N7+J6 -> 0 | O6: SCR 400A | Q6: ICER 600A | R6: 13
G7: SCR 450A | I7: ICER 700A | K7: SCR 450A | L7: =H7+'2026.9.10'!L8 -> 0 | M7: ICER 700A | N7: ='2026.9.10'!N8+J7 -> 0 | O7: SCR 450A | Q7: ICER 700A
G8: SCR 500A | I8: ICER 800A | K8: SCR 500A | L8: =H8+'2026.9.10'!L9 -> 0 | M8: ICER 800A | N8: ='2026.9.10'!N9+J8 -> 8 | O8: SCR 500A | P8: 12 | Q8: ICER 800A | R8: 10
G9: SCR N500A | I9: ICER 1000A | J9: 2 | K9: SCR N500A | L9: =H9+'2026.9.10'!L10 -> 0 | M9: ICER 1000A | N9: ='2026.9.10'!N10+J9 -> 6 | O9: SCR N500A | P9: 6 | Q9: ICER 1000A | R9: 10
G10: SCR 5K N500A | K10: SCR 5K N500A | L10: =H10+'2026.9.10'!L11 -> 0 | O10: SCR 5K N500A | P10: 8
A11: DAMPER 조립 자재 재고현황 | G11: SCR 550A | K11: SCR 550A | L11: =H11+'2026.9.10'!L12 -> 0 | O11: SCR 550A
G12: SCR N550A | K12: SCR N550A | L12: =H12+'2026.9.10'!L13 -> 0 | O12: SCR N550A
G13: SCR 5K N550A | K13: SCR 5K N550A | L13: =H13+'2026.9.10'!L14 -> 0 | O13: SCR 5K N550A
G14: SCR 600A | K14: SCR 600A | L14: =H14+'2026.9.10'!L15 -> 0 | O14: SCR 600A | P14: 28
G15: SCR N600A | K15: SCR N600A | L15: =H15+'2026.9.10'!L16 -> 0 | O15: SCR N600A
G16: SCR 5K N600A | K16: SCR 5K 600A | L16: =H16+'2026.9.10'!L17 -> 0 | O16: SCR 5K N600A | P16: 4
G17: SCR 650A | K17: SCR 650A | L17: =H17+'2026.9.10'!L18 -> 0 | O17: SCR 650A | P17: 7
G18: SCR 5K 650A | K18: SCR 5K 650A | L18: =H18+'2026.9.10'!L19 -> 0 | O18: SCR 5K 650A | P18: 4
G19: SCR 700A | K19: SCR 700A | L19: =H19+'2026.9.10'!L20 -> 0 | O19: SCR 700A | P19: 5
G20: SCR 750A | K20: SCR 750A | L20: =H20+'2026.9.10'!L21 -> 0 | O20: SCR 750A | P20: 3
G21: SCR 800A | K21: SCR 800A | L21: =H21+'2026.9.10'!L22 -> 0 | O21: SCR 800A | P21: 17
G22: SCR 5K 400A(세) | K22: SCR 5K 400A(세) | L22: =H22+'2026.9.10'!L23 -> 0 | O22: SCR 5K 400A(세)
G23: SCR 5K 600A(세) | K23: SCR 5K 600A(세) | L23: =H23+'2026.9.10'!L24 -> 0 | O23: SCR 5K 600A(세)
G24: SCR 2200A | K24: SCR 2200A | L24: =H24+'2026.9.10'!L25 -> 1 | O24: SCR 2200A
G25: SCR 2400A | K25: SCR 2400A | L25: =H25+'2026.9.10'!L26 -> 0 | O25: SCR 2400A
L26: =SUM(L4:L25) -> 1 | N26: =SUM(N4:N25) -> 14 | P26: =SUM(P4:P25) -> 100 | R26: =SUM(R4:R25) -> 33
A28: 자재명 | B28: 재질 | C28: 수량/1대 | D28: 적용모델 | E28: 자재규격 | F28: 전일재고 | G28: 투입수량 | H28: 분실/파손/불용 | I28: 입고수량 | J28: 현재재고 | K28: 조립가능대수 | L28: 안전재고알람 | M28: 투입계획 | N28: 과부족
A29: Disc | B29: SS400/SB480 | C29: 1 | D29: SCR N400A | G29: =H4*C29 -> 0 | J29: =F29+I29-G29-H29 -> 0 | K29: =J29/C29 -> 0 | L29: =IF(J29<M29,119,"") | M29: =P4*C29 -> 0 | N29: =J29-M29 -> 0
A30: Disc | B30: SS400/SB480 | C30: 1 | D30: SCR N450 | G30: =H5*C30 -> 0 | J30: =F30+I30-G30-H30 -> 0 | K30: =J30/C30 -> 0 | L30: =IF(J30<M30,119,"") -> 119 | M30: =P5*C30 -> 6 | N30: =J30-M30 -> -6
A31: Disc | B31: SS400/SB480 | C31: 1 | D31: SCR 400A | G31: =H6*C31 -> 0 | J31: =F31+I31-G31-H31 -> 0 | K31: =J31/C31 -> 0 | L31: =IF(J31<M31,119,"") | M31: =P6*C31 -> 0 | N31: =J31-M31 -> 0
A32: Disc | B32: SS400/SB480 | C32: 1 | D32: SCR 450A | G32: =H7*C32 -> 0 | J32: =F32+I32-G32-H32 -> 0 | K32: =J32/C32 -> 0 | L32: =IF(J32<M32,119,"") | M32: =P7*C32 -> 0 | N32: =J32-M32 -> 0
A33: Disc | B33: SS400/SB480 | C33: 1 | D33: SCR 500A | G33: =H8*C33 -> 0 | J33: =F33+I33-G33-H33 -> 0 | K33: =J33/C33 -> 0 | L33: =IF(J33<M33,119,"") -> 119 | M33: =P8*C33 -> 12 | N33: =J33-M33 -> -12
A34: Disc | B34: SS400/SB480 | C34: 1 | D34: SCR N500A | G34: =H9*C34 -> 0 | J34: =F34+I34-G34-H34 -> 0 | K34: =J34/C34 -> 0 | L34: =IF(J34<M34,119,"") -> 119 | M34: =P9*C34 -> 6 | N34: =J34-M34 -> -6
A35: Disc | B35: SS400/SB480 | C35: 1 | D35: SCR 5K N500A | G35: =H10*C35 -> 0 | J35: =F35+I35-G35-H35 -> 0 | K35: =J35/C35 -> 0 | L35: =IF(J35<M35,119,"") -> 119 | M35: =P10*C35 -> 8 | N35: =J35-M35 -> -8
A36: Disc | B36: SS400/SB480 | C36: 1 | D36: SCR 550A | G36: =H11*C36 -> 0 | J36: =F36+I36-G36-H36 -> 0 | K36: =J36/C36 -> 0 | L36: =IF(J36<M36,119,"") | M36: =P11*C36 -> 0 | N36: =J36-M36 -> 0
A37: Disc | B37: SS400/SB480 | C37: 1 | D37: SCR N550A | G37: =H12*C37 -> 0 | J37: =F37+I37-G37-H37 -> 0 | K37: =J37/C37 -> 0 | L37: =IF(J37<M37,119,"") | M37: =P12*C37 -> 0 | N37: =J37-M37 -> 0
A38: Disc | B38: SS400/SB480 | C38: 1 | D38: SCR 5K N550A | G38: =H13*C38 -> 0 | J38: =F38+I38-G38-H38 -> 0 | K38: =J38/C38 -> 0 | L38: =IF(J38<M38,119,"") | M38: =P13*C38 -> 0 | N38: =J38-M38 -> 0
A39: Disc | B39: SS400/SB480 | C39: 1 | D39: SCR 600A | G39: =H14*C39 -> 0 | J39: =F39+I39-G39-H39 -> 0 | K39: =J39/C39 -> 0 | L39: =IF(J39<M39,119,"") -> 119 | M39: =P14*C39 -> 28 | N39: =J39-M39 -> -28
A40: Disc | B40: SS400/SB480 | C40: 1 | D40: SCR N600A | G40: =H15*C40 -> 0 | J40: =F40+I40-G40-H40 -> 0 | K40: =J40/C40 -> 0 | L40: =IF(J40<M40,119,"") | M40: =P15*C40 -> 0 | N40: =J40-M40 -> 0
... A50: Disc | B50: SS400 | C50: 1 | D50: SCR 2400A | G50: =H25*C50 -> 0 | J50: =F50+I50-G50-H50 -> 0 | K50: =J50/C50 -> 0 | L50: =IF(J50<M50,119,"") | M50: =P25*C50 -> 0 | N50: =J50-M50 -> 0
A51: Disc | B51: SUS316 | C51: 1 | D51: ICER 600A | G51: =J6*C51 -> 0 | J51: =F51+I51-G51-H51 -> 0 | K51: =J51/C51 -> 0 | L51: =IF(J51<M51,119,"") -> 119 | M51: =R6*C51 -> 13 | N51: =J51-M51 -> -13
...

Sheet 2026.9.14
G2: DAMPER 모델별 조립실적(2026.9.8~) | O2: DAMPER 모델별 조립계획(2026.10)
G3: SCR-LP | H3: 금일조립수량 | I3: ICER | J3: 금일조립수량 | K3: SCR-LP | L3: 누계 | M3: ICER | N3: 누계 | O3: SCR-LP | P3: 10월계획 | Q3: ICER | R3: 10월계획
G4: SCR N400A | K4: SCR N400A | L4: =H4+'2026.9.10'!L5 -> 0 | O4: SCR N400A
G5: SCR N450 | K5: SCR N450 | L5: =H5+'2026.9.10'!L6 -> 0 | O5: SCR N450 | P5: 6
G6: SCR 400A | I6: ICER 600A | K6: SCR 400A | L6: =H6+'2026.9.10'!L7 -> 0 | M6: ICER 600A | N6: ='2026.9.10'!N7+J6 -> 0 | O6: SCR 400A | Q6: ICER 600A | R6: 13
G7: SCR 450A | I7: ICER 700A | K7: SCR 450A | L7: =H7+'2026.9.10'!L8 -> 0 | M7: ICER 700A | N7: ='2026.9.10'!N8+J7 -> 0 | O7: SCR 450A | Q7: ICER 700A
G8: SCR 500A | I8: ICER 800A | K8: SCR 500A | L8: =H8+'2026.9.10'!L9 -> 0 | M8: ICER 800A | N8: ='2026.9.10'!N9+J8 -> 8 | O8: SCR 500A | P8: 12 | Q8: ICER 800A | R8: 10
G9: SCR N500A | I9: ICER 1000A | K9: SCR N500A | L9: =H9+'2026.9.10'!L10 -> 0 | M9: ICER 1000A | N9: ='2026.9.10'!N10+J9 -> 4 | O9: SCR N500A | P9: 6 | Q9: ICER 1000A | R9: 10
G10: SCR 5K N500A | K10: SCR 5K N500A | L10: =H10+'2026.9.10'!L11 -> 0 | O10: SCR 5K N500A | P10: 8
A11: DAMPER 조립 자재 재고현황 | G11: SCR 550A | K11: SCR 550A | L11: =H11+'2026.9.10'!L12 -> 0 | O11: SCR 550A
G12: SCR N550A | K12: SCR N550A | L12: =H12+'2026.9.10'!L13 -> 0 | O12: SCR N550A
G13: SCR 5K N550A | K13: SCR 5K N550A | L13: =H13+'2026.9.10'!L14 -> 0 | O13: SCR 5K N550A
G14: SCR 600A(SS) | K14: SCR 600A(SS) | L14: =H14+'2026.9.10'!L15 -> 0 | O14: SCR 600A(SS) | P14: 28
G15: SCR 600A(SB) | K15: SCR 600A(SB) | O15: SCR 600A(SB)
G16: SCR N600A(SS) | K16: SCR N600A(SS) | L16: =H16+'2026.9.10'!L16 -> 0 | O16: SCR N600A(SS)
G17: SCR N600A(SB) | K17: SCR N600A(SB) | O17: SCR N600A(SB)
G18: SCR 5K N600A | K18: SCR 5K N600A | L18: =H18+'2026.9.10'!L17 -> 0 | O18: SCR 5K N600A | P18: 4
G19: SCR 650A(SS) | K19: SCR 650A(SS) | L19: =H19+'2026.9.10'!L18 -> 0 | O19: SCR 650A(SS) | P19: 7
G20: SCR 650A(SB) | K20: SCR 650A(SB) | O20: SCR 650A(SB)
G21: SCR DIN 650A(SS) | K21: SCR DIN 650A(SS) | O21: SCR DIN 650A(SS)
G22: SCR DIN 650A(SB) | K22: SCR DIN 650A(SB) | O22: SCR DIN 650A(SB)
G23: SCR 5K 650A | K23: SCR 5K 650A | L23: =H23+'2026.9.10'!L19 -> 0 | O23: SCR 5K 650A | P23: 4
G24: SCR 700A(SS) | K24: SCR 700A(SS) | L24: =H24+'2026.9.10'!L20 -> 0 | O24: SCR 700A(SS) | P24: 5
G25: SCR 700A(SB) | K25: SCR 700A(SB) | O25: SCR 700A(SB)
G26: SCR DIN 700A(SS) | K26: SCR DIN 700A(SS) | O26: SCR DIN 700A(SS)
G27: SCR DIN 700A(SB) | K27: SCR DIN 700A(SB) | O27: SCR DIN 700A(SB)
G28: SCR 750A(SS) | K28: SCR 750A(SS) | L28: =H28+'2026.9.10'!L21 -> 0 | O28: SCR 750A(SS) | P28: 3
G29: SCR 750A(SB) | K29: SCR 750A(SB) | O29: SCR 750A(SB)
G30: SCR DIN 750A(SS) | K30: SCR DIN 750A(SS) | O30: SCR DIN 750A(SS)
G31: SCR DIN 750A(SB) | K31: SCR DIN 750A(SB) | O31: SCR DIN 750A(SB)
G32: SCR 800A(SS) | K32: SCR 800A(SS) | L32: =H32+'2026.9.10'!L22 -> 0 | O32: SCR 800A(SS) | P32: 17
G33: SCR 800A(SB) | K33: SCR 800A(SB) | O33: SCR 800A(SB)
G34: SCR DIN 800A(SS) | K34: SCR DIN 800A(SS) | O34: SCR DIN 800A(SS)
G35: SCR DIN 800A(SB) | K35: SCR DIN 800A(SB) | O35: SCR DIN 800A(SB)
G36: SCR 5K 400A(세) | K36: SCR 5K 400A(세) | L36: =H36+'2026.9.10'!L23 -> 0 | O36: SCR 5K 400A(세)
G37: SCR 5K 600A(세) | K37: SCR 5K 600A(세) | L37: =H37+'2026.9.10'!L24 -> 0 | O37: SCR 5K 600A(세)
G38: SCR 2200A | K38: SCR 2200A | L38: =H38+'2026.9.10'!L25 -> 1 | O38: SCR 2200A
G39: SCR 2400A | K39: SCR 2400A | L39: =H39+'2026.9.10'!L26 -> 0 | O39: SCR 2400A
L40: =SUM(L4:L39) -> 1 | N40: =SUM(N4:N39) -> 12 | P40: =SUM(P4:P39) -> 100 | R40: =SUM(R4:R39) -> 33
A42: 자재명 | B42: 재질 | C42: 수량/1대 | D42: 적용모델 | E42: 자재규격 | F42: 전일재고 | G42: 투입수량 | H42: 분실/파손/불용 | I42: 입고수량 | J42: 현재재고 | K42: 조립가능대수 | L42: 안전재고알람 | M42: 투입계획 | N42: 과부족
...

Sheet Sheet1
